2023-06-14 12:54:24,011 - INFO - Logger set up with log level: 20(info)
2023-06-14 12:54:24,013 - INFO - Log file: logs/langflow.log
2023-06-14 12:54:44,856 - ERROR - File  is not accepted
Traceback (most recent call last):
  File "/Library/Frameworks/Python.framework/Versions/3.11/lib/python3.11/site-packages/langflow/api/validate.py", line 47, in post_validate_node
    graph = build_graph(data)
            ^^^^^^^^^^^^^^^^^
  File "/Library/Frameworks/Python.framework/Versions/3.11/lib/python3.11/site-packages/langflow/interface/run.py", line 50, in build_graph
    return Graph(nodes, edges)
           ^^^^^^^^^^^^^^^^^^^
  File "/Library/Frameworks/Python.framework/Versions/3.11/lib/python3.11/site-packages/langflow/graph/graph.py", line 43, in __init__
    self._build_graph()
  File "/Library/Frameworks/Python.framework/Versions/3.11/lib/python3.11/site-packages/langflow/graph/graph.py", line 56, in _build_graph
    node._build_params()
  File "/Library/Frameworks/Python.framework/Versions/3.11/lib/python3.11/site-packages/langflow/graph/base.py", line 93, in _build_params
    file_path = cache_utils.save_binary_file(
                ^^^^^^^^^^^^^^^^^^^^^^^^^^^^^
  File "/Library/Frameworks/Python.framework/Versions/3.11/lib/python3.11/site-packages/langflow/cache/base.py", line 25, in wrapper
    return func(*args, **kwargs)
           ^^^^^^^^^^^^^^^^^^^^^
  File "/Library/Frameworks/Python.framework/Versions/3.11/lib/python3.11/site-packages/langflow/cache/base.py", line 119, in save_binary_file
    raise ValueError(f"File {file_name} is not accepted")
ValueError: File  is not accepted
2023-06-14 12:54:44,859 - ERROR - File  is not accepted
Traceback (most recent call last):
  File "/Library/Frameworks/Python.framework/Versions/3.11/lib/python3.11/site-packages/langflow/api/validate.py", line 47, in post_validate_node
    graph = build_graph(data)
            ^^^^^^^^^^^^^^^^^
  File "/Library/Frameworks/Python.framework/Versions/3.11/lib/python3.11/site-packages/langflow/interface/run.py", line 50, in build_graph
    return Graph(nodes, edges)
           ^^^^^^^^^^^^^^^^^^^
  File "/Library/Frameworks/Python.framework/Versions/3.11/lib/python3.11/site-packages/langflow/graph/graph.py", line 43, in __init__
    self._build_graph()
  File "/Library/Frameworks/Python.framework/Versions/3.11/lib/python3.11/site-packages/langflow/graph/graph.py", line 56, in _build_graph
    node._build_params()
  File "/Library/Frameworks/Python.framework/Versions/3.11/lib/python3.11/site-packages/langflow/graph/base.py", line 93, in _build_params
    file_path = cache_utils.save_binary_file(
                ^^^^^^^^^^^^^^^^^^^^^^^^^^^^^
  File "/Library/Frameworks/Python.framework/Versions/3.11/lib/python3.11/site-packages/langflow/cache/base.py", line 25, in wrapper
    return func(*args, **kwargs)
           ^^^^^^^^^^^^^^^^^^^^^
  File "/Library/Frameworks/Python.framework/Versions/3.11/lib/python3.11/site-packages/langflow/cache/base.py", line 119, in save_binary_file
    raise ValueError(f"File {file_name} is not accepted")
ValueError: File  is not accepted
2023-06-14 12:54:44,861 - ERROR - File  is not accepted
Traceback (most recent call last):
  File "/Library/Frameworks/Python.framework/Versions/3.11/lib/python3.11/site-packages/langflow/api/validate.py", line 47, in post_validate_node
    graph = build_graph(data)
            ^^^^^^^^^^^^^^^^^
  File "/Library/Frameworks/Python.framework/Versions/3.11/lib/python3.11/site-packages/langflow/interface/run.py", line 50, in build_graph
    return Graph(nodes, edges)
           ^^^^^^^^^^^^^^^^^^^
  File "/Library/Frameworks/Python.framework/Versions/3.11/lib/python3.11/site-packages/langflow/graph/graph.py", line 43, in __init__
    self._build_graph()
  File "/Library/Frameworks/Python.framework/Versions/3.11/lib/python3.11/site-packages/langflow/graph/graph.py", line 56, in _build_graph
    node._build_params()
  File "/Library/Frameworks/Python.framework/Versions/3.11/lib/python3.11/site-packages/langflow/graph/base.py", line 93, in _build_params
    file_path = cache_utils.save_binary_file(
                ^^^^^^^^^^^^^^^^^^^^^^^^^^^^^
  File "/Library/Frameworks/Python.framework/Versions/3.11/lib/python3.11/site-packages/langflow/cache/base.py", line 25, in wrapper
    return func(*args, **kwargs)
           ^^^^^^^^^^^^^^^^^^^^^
  File "/Library/Frameworks/Python.framework/Versions/3.11/lib/python3.11/site-packages/langflow/cache/base.py", line 119, in save_binary_file
    raise ValueError(f"File {file_name} is not accepted")
ValueError: File  is not accepted
2023-06-14 12:54:44,867 - ERROR - File  is not accepted
Traceback (most recent call last):
  File "/Library/Frameworks/Python.framework/Versions/3.11/lib/python3.11/site-packages/langflow/api/validate.py", line 47, in post_validate_node
    graph = build_graph(data)
            ^^^^^^^^^^^^^^^^^
  File "/Library/Frameworks/Python.framework/Versions/3.11/lib/python3.11/site-packages/langflow/interface/run.py", line 50, in build_graph
    return Graph(nodes, edges)
           ^^^^^^^^^^^^^^^^^^^
  File "/Library/Frameworks/Python.framework/Versions/3.11/lib/python3.11/site-packages/langflow/graph/graph.py", line 43, in __init__
    self._build_graph()
  File "/Library/Frameworks/Python.framework/Versions/3.11/lib/python3.11/site-packages/langflow/graph/graph.py", line 56, in _build_graph
    node._build_params()
  File "/Library/Frameworks/Python.framework/Versions/3.11/lib/python3.11/site-packages/langflow/graph/base.py", line 93, in _build_params
    file_path = cache_utils.save_binary_file(
                ^^^^^^^^^^^^^^^^^^^^^^^^^^^^^
  File "/Library/Frameworks/Python.framework/Versions/3.11/lib/python3.11/site-packages/langflow/cache/base.py", line 25, in wrapper
    return func(*args, **kwargs)
           ^^^^^^^^^^^^^^^^^^^^^
  File "/Library/Frameworks/Python.framework/Versions/3.11/lib/python3.11/site-packages/langflow/cache/base.py", line 119, in save_binary_file
    raise ValueError(f"File {file_name} is not accepted")
ValueError: File  is not accepted
2023-06-14 12:54:44,870 - ERROR - File  is not accepted
Traceback (most recent call last):
  File "/Library/Frameworks/Python.framework/Versions/3.11/lib/python3.11/site-packages/langflow/api/validate.py", line 47, in post_validate_node
    graph = build_graph(data)
            ^^^^^^^^^^^^^^^^^
  File "/Library/Frameworks/Python.framework/Versions/3.11/lib/python3.11/site-packages/langflow/interface/run.py", line 50, in build_graph
    return Graph(nodes, edges)
           ^^^^^^^^^^^^^^^^^^^
  File "/Library/Frameworks/Python.framework/Versions/3.11/lib/python3.11/site-packages/langflow/graph/graph.py", line 43, in __init__
    self._build_graph()
  File "/Library/Frameworks/Python.framework/Versions/3.11/lib/python3.11/site-packages/langflow/graph/graph.py", line 56, in _build_graph
    node._build_params()
  File "/Library/Frameworks/Python.framework/Versions/3.11/lib/python3.11/site-packages/langflow/graph/base.py", line 93, in _build_params
    file_path = cache_utils.save_binary_file(
                ^^^^^^^^^^^^^^^^^^^^^^^^^^^^^
  File "/Library/Frameworks/Python.framework/Versions/3.11/lib/python3.11/site-packages/langflow/cache/base.py", line 25, in wrapper
    return func(*args, **kwargs)
           ^^^^^^^^^^^^^^^^^^^^^
  File "/Library/Frameworks/Python.framework/Versions/3.11/lib/python3.11/site-packages/langflow/cache/base.py", line 119, in save_binary_file
    raise ValueError(f"File {file_name} is not accepted")
ValueError: File  is not accepted
2023-06-14 12:54:44,878 - ERROR - File  is not accepted
Traceback (most recent call last):
  File "/Library/Frameworks/Python.framework/Versions/3.11/lib/python3.11/site-packages/langflow/api/validate.py", line 47, in post_validate_node
    graph = build_graph(data)
            ^^^^^^^^^^^^^^^^^
  File "/Library/Frameworks/Python.framework/Versions/3.11/lib/python3.11/site-packages/langflow/interface/run.py", line 50, in build_graph
    return Graph(nodes, edges)
           ^^^^^^^^^^^^^^^^^^^
  File "/Library/Frameworks/Python.framework/Versions/3.11/lib/python3.11/site-packages/langflow/graph/graph.py", line 43, in __init__
    self._build_graph()
  File "/Library/Frameworks/Python.framework/Versions/3.11/lib/python3.11/site-packages/langflow/graph/graph.py", line 56, in _build_graph
    node._build_params()
  File "/Library/Frameworks/Python.framework/Versions/3.11/lib/python3.11/site-packages/langflow/graph/base.py", line 93, in _build_params
    file_path = cache_utils.save_binary_file(
                ^^^^^^^^^^^^^^^^^^^^^^^^^^^^^
  File "/Library/Frameworks/Python.framework/Versions/3.11/lib/python3.11/site-packages/langflow/cache/base.py", line 25, in wrapper
    return func(*args, **kwargs)
           ^^^^^^^^^^^^^^^^^^^^^
  File "/Library/Frameworks/Python.framework/Versions/3.11/lib/python3.11/site-packages/langflow/cache/base.py", line 119, in save_binary_file
    raise ValueError(f"File {file_name} is not accepted")
ValueError: File  is not accepted
2023-06-14 12:54:44,963 - ERROR - File  is not accepted
Traceback (most recent call last):
  File "/Library/Frameworks/Python.framework/Versions/3.11/lib/python3.11/site-packages/langflow/api/validate.py", line 47, in post_validate_node
    graph = build_graph(data)
            ^^^^^^^^^^^^^^^^^
  File "/Library/Frameworks/Python.framework/Versions/3.11/lib/python3.11/site-packages/langflow/interface/run.py", line 50, in build_graph
    return Graph(nodes, edges)
           ^^^^^^^^^^^^^^^^^^^
  File "/Library/Frameworks/Python.framework/Versions/3.11/lib/python3.11/site-packages/langflow/graph/graph.py", line 43, in __init__
    self._build_graph()
  File "/Library/Frameworks/Python.framework/Versions/3.11/lib/python3.11/site-packages/langflow/graph/graph.py", line 56, in _build_graph
    node._build_params()
  File "/Library/Frameworks/Python.framework/Versions/3.11/lib/python3.11/site-packages/langflow/graph/base.py", line 93, in _build_params
    file_path = cache_utils.save_binary_file(
                ^^^^^^^^^^^^^^^^^^^^^^^^^^^^^
  File "/Library/Frameworks/Python.framework/Versions/3.11/lib/python3.11/site-packages/langflow/cache/base.py", line 25, in wrapper
    return func(*args, **kwargs)
           ^^^^^^^^^^^^^^^^^^^^^
  File "/Library/Frameworks/Python.framework/Versions/3.11/lib/python3.11/site-packages/langflow/cache/base.py", line 119, in save_binary_file
    raise ValueError(f"File {file_name} is not accepted")
ValueError: File  is not accepted
2023-06-14 12:54:45,950 - ERROR - File  is not accepted
Traceback (most recent call last):
  File "/Library/Frameworks/Python.framework/Versions/3.11/lib/python3.11/site-packages/langflow/api/validate.py", line 47, in post_validate_node
    graph = build_graph(data)
            ^^^^^^^^^^^^^^^^^
  File "/Library/Frameworks/Python.framework/Versions/3.11/lib/python3.11/site-packages/langflow/interface/run.py", line 50, in build_graph
    return Graph(nodes, edges)
           ^^^^^^^^^^^^^^^^^^^
  File "/Library/Frameworks/Python.framework/Versions/3.11/lib/python3.11/site-packages/langflow/graph/graph.py", line 43, in __init__
    self._build_graph()
  File "/Library/Frameworks/Python.framework/Versions/3.11/lib/python3.11/site-packages/langflow/graph/graph.py", line 56, in _build_graph
    node._build_params()
  File "/Library/Frameworks/Python.framework/Versions/3.11/lib/python3.11/site-packages/langflow/graph/base.py", line 93, in _build_params
    file_path = cache_utils.save_binary_file(
                ^^^^^^^^^^^^^^^^^^^^^^^^^^^^^
  File "/Library/Frameworks/Python.framework/Versions/3.11/lib/python3.11/site-packages/langflow/cache/base.py", line 25, in wrapper
    return func(*args, **kwargs)
           ^^^^^^^^^^^^^^^^^^^^^
  File "/Library/Frameworks/Python.framework/Versions/3.11/lib/python3.11/site-packages/langflow/cache/base.py", line 119, in save_binary_file
    raise ValueError(f"File {file_name} is not accepted")
ValueError: File  is not accepted
2023-06-14 12:54:45,950 - ERROR - File  is not accepted
Traceback (most recent call last):
  File "/Library/Frameworks/Python.framework/Versions/3.11/lib/python3.11/site-packages/langflow/api/validate.py", line 47, in post_validate_node
    graph = build_graph(data)
            ^^^^^^^^^^^^^^^^^
  File "/Library/Frameworks/Python.framework/Versions/3.11/lib/python3.11/site-packages/langflow/interface/run.py", line 50, in build_graph
    return Graph(nodes, edges)
           ^^^^^^^^^^^^^^^^^^^
  File "/Library/Frameworks/Python.framework/Versions/3.11/lib/python3.11/site-packages/langflow/graph/graph.py", line 43, in __init__
    self._build_graph()
  File "/Library/Frameworks/Python.framework/Versions/3.11/lib/python3.11/site-packages/langflow/graph/graph.py", line 56, in _build_graph
    node._build_params()
  File "/Library/Frameworks/Python.framework/Versions/3.11/lib/python3.11/site-packages/langflow/graph/base.py", line 93, in _build_params
    file_path = cache_utils.save_binary_file(
                ^^^^^^^^^^^^^^^^^^^^^^^^^^^^^
  File "/Library/Frameworks/Python.framework/Versions/3.11/lib/python3.11/site-packages/langflow/cache/base.py", line 25, in wrapper
    return func(*args, **kwargs)
           ^^^^^^^^^^^^^^^^^^^^^
  File "/Library/Frameworks/Python.framework/Versions/3.11/lib/python3.11/site-packages/langflow/cache/base.py", line 119, in save_binary_file
    raise ValueError(f"File {file_name} is not accepted")
ValueError: File  is not accepted
2023-06-14 12:54:45,967 - ERROR - File  is not accepted
Traceback (most recent call last):
  File "/Library/Frameworks/Python.framework/Versions/3.11/lib/python3.11/site-packages/langflow/api/validate.py", line 47, in post_validate_node
    graph = build_graph(data)
            ^^^^^^^^^^^^^^^^^
  File "/Library/Frameworks/Python.framework/Versions/3.11/lib/python3.11/site-packages/langflow/interface/run.py", line 50, in build_graph
    return Graph(nodes, edges)
           ^^^^^^^^^^^^^^^^^^^
  File "/Library/Frameworks/Python.framework/Versions/3.11/lib/python3.11/site-packages/langflow/graph/graph.py", line 43, in __init__
    self._build_graph()
  File "/Library/Frameworks/Python.framework/Versions/3.11/lib/python3.11/site-packages/langflow/graph/graph.py", line 56, in _build_graph
    node._build_params()
  File "/Library/Frameworks/Python.framework/Versions/3.11/lib/python3.11/site-packages/langflow/graph/base.py", line 93, in _build_params
    file_path = cache_utils.save_binary_file(
                ^^^^^^^^^^^^^^^^^^^^^^^^^^^^^
  File "/Library/Frameworks/Python.framework/Versions/3.11/lib/python3.11/site-packages/langflow/cache/base.py", line 25, in wrapper
    return func(*args, **kwargs)
           ^^^^^^^^^^^^^^^^^^^^^
  File "/Library/Frameworks/Python.framework/Versions/3.11/lib/python3.11/site-packages/langflow/cache/base.py", line 119, in save_binary_file
    raise ValueError(f"File {file_name} is not accepted")
ValueError: File  is not accepted
2023-06-14 12:54:45,981 - ERROR - File  is not accepted
Traceback (most recent call last):
  File "/Library/Frameworks/Python.framework/Versions/3.11/lib/python3.11/site-packages/langflow/api/validate.py", line 47, in post_validate_node
    graph = build_graph(data)
            ^^^^^^^^^^^^^^^^^
  File "/Library/Frameworks/Python.framework/Versions/3.11/lib/python3.11/site-packages/langflow/interface/run.py", line 50, in build_graph
    return Graph(nodes, edges)
           ^^^^^^^^^^^^^^^^^^^
  File "/Library/Frameworks/Python.framework/Versions/3.11/lib/python3.11/site-packages/langflow/graph/graph.py", line 43, in __init__
    self._build_graph()
  File "/Library/Frameworks/Python.framework/Versions/3.11/lib/python3.11/site-packages/langflow/graph/graph.py", line 56, in _build_graph
    node._build_params()
  File "/Library/Frameworks/Python.framework/Versions/3.11/lib/python3.11/site-packages/langflow/graph/base.py", line 93, in _build_params
    file_path = cache_utils.save_binary_file(
                ^^^^^^^^^^^^^^^^^^^^^^^^^^^^^
  File "/Library/Frameworks/Python.framework/Versions/3.11/lib/python3.11/site-packages/langflow/cache/base.py", line 25, in wrapper
    return func(*args, **kwargs)
           ^^^^^^^^^^^^^^^^^^^^^
  File "/Library/Frameworks/Python.framework/Versions/3.11/lib/python3.11/site-packages/langflow/cache/base.py", line 119, in save_binary_file
    raise ValueError(f"File {file_name} is not accepted")
ValueError: File  is not accepted
2023-06-14 12:54:45,986 - ERROR - File  is not accepted
Traceback (most recent call last):
  File "/Library/Frameworks/Python.framework/Versions/3.11/lib/python3.11/site-packages/langflow/api/validate.py", line 47, in post_validate_node
    graph = build_graph(data)
            ^^^^^^^^^^^^^^^^^
  File "/Library/Frameworks/Python.framework/Versions/3.11/lib/python3.11/site-packages/langflow/interface/run.py", line 50, in build_graph
    return Graph(nodes, edges)
           ^^^^^^^^^^^^^^^^^^^
  File "/Library/Frameworks/Python.framework/Versions/3.11/lib/python3.11/site-packages/langflow/graph/graph.py", line 43, in __init__
    self._build_graph()
  File "/Library/Frameworks/Python.framework/Versions/3.11/lib/python3.11/site-packages/langflow/graph/graph.py", line 56, in _build_graph
    node._build_params()
  File "/Library/Frameworks/Python.framework/Versions/3.11/lib/python3.11/site-packages/langflow/graph/base.py", line 93, in _build_params
    file_path = cache_utils.save_binary_file(
                ^^^^^^^^^^^^^^^^^^^^^^^^^^^^^
  File "/Library/Frameworks/Python.framework/Versions/3.11/lib/python3.11/site-packages/langflow/cache/base.py", line 25, in wrapper
    return func(*args, **kwargs)
           ^^^^^^^^^^^^^^^^^^^^^
  File "/Library/Frameworks/Python.framework/Versions/3.11/lib/python3.11/site-packages/langflow/cache/base.py", line 119, in save_binary_file
    raise ValueError(f"File {file_name} is not accepted")
ValueError: File  is not accepted
2023-06-14 12:54:45,993 - ERROR - File  is not accepted
Traceback (most recent call last):
  File "/Library/Frameworks/Python.framework/Versions/3.11/lib/python3.11/site-packages/langflow/api/validate.py", line 47, in post_validate_node
    graph = build_graph(data)
            ^^^^^^^^^^^^^^^^^
  File "/Library/Frameworks/Python.framework/Versions/3.11/lib/python3.11/site-packages/langflow/interface/run.py", line 50, in build_graph
    return Graph(nodes, edges)
           ^^^^^^^^^^^^^^^^^^^
  File "/Library/Frameworks/Python.framework/Versions/3.11/lib/python3.11/site-packages/langflow/graph/graph.py", line 43, in __init__
    self._build_graph()
  File "/Library/Frameworks/Python.framework/Versions/3.11/lib/python3.11/site-packages/langflow/graph/graph.py", line 56, in _build_graph
    node._build_params()
  File "/Library/Frameworks/Python.framework/Versions/3.11/lib/python3.11/site-packages/langflow/graph/base.py", line 93, in _build_params
    file_path = cache_utils.save_binary_file(
                ^^^^^^^^^^^^^^^^^^^^^^^^^^^^^
  File "/Library/Frameworks/Python.framework/Versions/3.11/lib/python3.11/site-packages/langflow/cache/base.py", line 25, in wrapper
    return func(*args, **kwargs)
           ^^^^^^^^^^^^^^^^^^^^^
  File "/Library/Frameworks/Python.framework/Versions/3.11/lib/python3.11/site-packages/langflow/cache/base.py", line 119, in save_binary_file
    raise ValueError(f"File {file_name} is not accepted")
ValueError: File  is not accepted
2023-06-14 12:54:46,034 - ERROR - File  is not accepted
Traceback (most recent call last):
  File "/Library/Frameworks/Python.framework/Versions/3.11/lib/python3.11/site-packages/langflow/api/validate.py", line 47, in post_validate_node
    graph = build_graph(data)
            ^^^^^^^^^^^^^^^^^
  File "/Library/Frameworks/Python.framework/Versions/3.11/lib/python3.11/site-packages/langflow/interface/run.py", line 50, in build_graph
    return Graph(nodes, edges)
           ^^^^^^^^^^^^^^^^^^^
  File "/Library/Frameworks/Python.framework/Versions/3.11/lib/python3.11/site-packages/langflow/graph/graph.py", line 43, in __init__
    self._build_graph()
  File "/Library/Frameworks/Python.framework/Versions/3.11/lib/python3.11/site-packages/langflow/graph/graph.py", line 56, in _build_graph
    node._build_params()
  File "/Library/Frameworks/Python.framework/Versions/3.11/lib/python3.11/site-packages/langflow/graph/base.py", line 93, in _build_params
    file_path = cache_utils.save_binary_file(
                ^^^^^^^^^^^^^^^^^^^^^^^^^^^^^
  File "/Library/Frameworks/Python.framework/Versions/3.11/lib/python3.11/site-packages/langflow/cache/base.py", line 25, in wrapper
    return func(*args, **kwargs)
           ^^^^^^^^^^^^^^^^^^^^^
  File "/Library/Frameworks/Python.framework/Versions/3.11/lib/python3.11/site-packages/langflow/cache/base.py", line 119, in save_binary_file
    raise ValueError(f"File {file_name} is not accepted")
ValueError: File  is not accepted
2023-06-14 12:55:11,287 - ERROR - File  is not accepted
Traceback (most recent call last):
  File "/Library/Frameworks/Python.framework/Versions/3.11/lib/python3.11/site-packages/langflow/api/validate.py", line 47, in post_validate_node
    graph = build_graph(data)
            ^^^^^^^^^^^^^^^^^
  File "/Library/Frameworks/Python.framework/Versions/3.11/lib/python3.11/site-packages/langflow/interface/run.py", line 50, in build_graph
    return Graph(nodes, edges)
           ^^^^^^^^^^^^^^^^^^^
  File "/Library/Frameworks/Python.framework/Versions/3.11/lib/python3.11/site-packages/langflow/graph/graph.py", line 43, in __init__
    self._build_graph()
  File "/Library/Frameworks/Python.framework/Versions/3.11/lib/python3.11/site-packages/langflow/graph/graph.py", line 56, in _build_graph
    node._build_params()
  File "/Library/Frameworks/Python.framework/Versions/3.11/lib/python3.11/site-packages/langflow/graph/base.py", line 93, in _build_params
    file_path = cache_utils.save_binary_file(
                ^^^^^^^^^^^^^^^^^^^^^^^^^^^^^
  File "/Library/Frameworks/Python.framework/Versions/3.11/lib/python3.11/site-packages/langflow/cache/base.py", line 25, in wrapper
    return func(*args, **kwargs)
           ^^^^^^^^^^^^^^^^^^^^^
  File "/Library/Frameworks/Python.framework/Versions/3.11/lib/python3.11/site-packages/langflow/cache/base.py", line 119, in save_binary_file
    raise ValueError(f"File {file_name} is not accepted")
ValueError: File  is not accepted
2023-06-14 12:55:11,294 - ERROR - File  is not accepted
Traceback (most recent call last):
  File "/Library/Frameworks/Python.framework/Versions/3.11/lib/python3.11/site-packages/langflow/api/validate.py", line 47, in post_validate_node
    graph = build_graph(data)
            ^^^^^^^^^^^^^^^^^
  File "/Library/Frameworks/Python.framework/Versions/3.11/lib/python3.11/site-packages/langflow/interface/run.py", line 50, in build_graph
    return Graph(nodes, edges)
           ^^^^^^^^^^^^^^^^^^^
  File "/Library/Frameworks/Python.framework/Versions/3.11/lib/python3.11/site-packages/langflow/graph/graph.py", line 43, in __init__
    self._build_graph()
  File "/Library/Frameworks/Python.framework/Versions/3.11/lib/python3.11/site-packages/langflow/graph/graph.py", line 56, in _build_graph
    node._build_params()
  File "/Library/Frameworks/Python.framework/Versions/3.11/lib/python3.11/site-packages/langflow/graph/base.py", line 93, in _build_params
    file_path = cache_utils.save_binary_file(
                ^^^^^^^^^^^^^^^^^^^^^^^^^^^^^
  File "/Library/Frameworks/Python.framework/Versions/3.11/lib/python3.11/site-packages/langflow/cache/base.py", line 25, in wrapper
    return func(*args, **kwargs)
           ^^^^^^^^^^^^^^^^^^^^^
  File "/Library/Frameworks/Python.framework/Versions/3.11/lib/python3.11/site-packages/langflow/cache/base.py", line 119, in save_binary_file
    raise ValueError(f"File {file_name} is not accepted")
ValueError: File  is not accepted
2023-06-14 12:55:11,326 - ERROR - File  is not accepted
Traceback (most recent call last):
  File "/Library/Frameworks/Python.framework/Versions/3.11/lib/python3.11/site-packages/langflow/api/validate.py", line 47, in post_validate_node
    graph = build_graph(data)
            ^^^^^^^^^^^^^^^^^
  File "/Library/Frameworks/Python.framework/Versions/3.11/lib/python3.11/site-packages/langflow/interface/run.py", line 50, in build_graph
    return Graph(nodes, edges)
           ^^^^^^^^^^^^^^^^^^^
  File "/Library/Frameworks/Python.framework/Versions/3.11/lib/python3.11/site-packages/langflow/graph/graph.py", line 43, in __init__
    self._build_graph()
  File "/Library/Frameworks/Python.framework/Versions/3.11/lib/python3.11/site-packages/langflow/graph/graph.py", line 56, in _build_graph
    node._build_params()
  File "/Library/Frameworks/Python.framework/Versions/3.11/lib/python3.11/site-packages/langflow/graph/base.py", line 93, in _build_params
    file_path = cache_utils.save_binary_file(
                ^^^^^^^^^^^^^^^^^^^^^^^^^^^^^
  File "/Library/Frameworks/Python.framework/Versions/3.11/lib/python3.11/site-packages/langflow/cache/base.py", line 25, in wrapper
    return func(*args, **kwargs)
           ^^^^^^^^^^^^^^^^^^^^^
  File "/Library/Frameworks/Python.framework/Versions/3.11/lib/python3.11/site-packages/langflow/cache/base.py", line 119, in save_binary_file
    raise ValueError(f"File {file_name} is not accepted")
ValueError: File  is not accepted
2023-06-14 12:55:11,339 - ERROR - File  is not accepted
Traceback (most recent call last):
  File "/Library/Frameworks/Python.framework/Versions/3.11/lib/python3.11/site-packages/langflow/api/validate.py", line 47, in post_validate_node
    graph = build_graph(data)
            ^^^^^^^^^^^^^^^^^
  File "/Library/Frameworks/Python.framework/Versions/3.11/lib/python3.11/site-packages/langflow/interface/run.py", line 50, in build_graph
    return Graph(nodes, edges)
           ^^^^^^^^^^^^^^^^^^^
  File "/Library/Frameworks/Python.framework/Versions/3.11/lib/python3.11/site-packages/langflow/graph/graph.py", line 43, in __init__
    self._build_graph()
  File "/Library/Frameworks/Python.framework/Versions/3.11/lib/python3.11/site-packages/langflow/graph/graph.py", line 56, in _build_graph
    node._build_params()
  File "/Library/Frameworks/Python.framework/Versions/3.11/lib/python3.11/site-packages/langflow/graph/base.py", line 93, in _build_params
    file_path = cache_utils.save_binary_file(
                ^^^^^^^^^^^^^^^^^^^^^^^^^^^^^
  File "/Library/Frameworks/Python.framework/Versions/3.11/lib/python3.11/site-packages/langflow/cache/base.py", line 25, in wrapper
    return func(*args, **kwargs)
           ^^^^^^^^^^^^^^^^^^^^^
  File "/Library/Frameworks/Python.framework/Versions/3.11/lib/python3.11/site-packages/langflow/cache/base.py", line 119, in save_binary_file
    raise ValueError(f"File {file_name} is not accepted")
ValueError: File  is not accepted
2023-06-14 12:55:11,347 - ERROR - File  is not accepted
Traceback (most recent call last):
  File "/Library/Frameworks/Python.framework/Versions/3.11/lib/python3.11/site-packages/langflow/api/validate.py", line 47, in post_validate_node
    graph = build_graph(data)
            ^^^^^^^^^^^^^^^^^
  File "/Library/Frameworks/Python.framework/Versions/3.11/lib/python3.11/site-packages/langflow/interface/run.py", line 50, in build_graph
    return Graph(nodes, edges)
           ^^^^^^^^^^^^^^^^^^^
  File "/Library/Frameworks/Python.framework/Versions/3.11/lib/python3.11/site-packages/langflow/graph/graph.py", line 43, in __init__
    self._build_graph()
  File "/Library/Frameworks/Python.framework/Versions/3.11/lib/python3.11/site-packages/langflow/graph/graph.py", line 56, in _build_graph
    node._build_params()
  File "/Library/Frameworks/Python.framework/Versions/3.11/lib/python3.11/site-packages/langflow/graph/base.py", line 93, in _build_params
    file_path = cache_utils.save_binary_file(
                ^^^^^^^^^^^^^^^^^^^^^^^^^^^^^
  File "/Library/Frameworks/Python.framework/Versions/3.11/lib/python3.11/site-packages/langflow/cache/base.py", line 25, in wrapper
    return func(*args, **kwargs)
           ^^^^^^^^^^^^^^^^^^^^^
  File "/Library/Frameworks/Python.framework/Versions/3.11/lib/python3.11/site-packages/langflow/cache/base.py", line 119, in save_binary_file
    raise ValueError(f"File {file_name} is not accepted")
ValueError: File  is not accepted
2023-06-14 12:55:11,347 - ERROR - File  is not accepted
Traceback (most recent call last):
  File "/Library/Frameworks/Python.framework/Versions/3.11/lib/python3.11/site-packages/langflow/api/validate.py", line 47, in post_validate_node
    graph = build_graph(data)
            ^^^^^^^^^^^^^^^^^
  File "/Library/Frameworks/Python.framework/Versions/3.11/lib/python3.11/site-packages/langflow/interface/run.py", line 50, in build_graph
    return Graph(nodes, edges)
           ^^^^^^^^^^^^^^^^^^^
  File "/Library/Frameworks/Python.framework/Versions/3.11/lib/python3.11/site-packages/langflow/graph/graph.py", line 43, in __init__
    self._build_graph()
  File "/Library/Frameworks/Python.framework/Versions/3.11/lib/python3.11/site-packages/langflow/graph/graph.py", line 56, in _build_graph
    node._build_params()
  File "/Library/Frameworks/Python.framework/Versions/3.11/lib/python3.11/site-packages/langflow/graph/base.py", line 93, in _build_params
    file_path = cache_utils.save_binary_file(
                ^^^^^^^^^^^^^^^^^^^^^^^^^^^^^
  File "/Library/Frameworks/Python.framework/Versions/3.11/lib/python3.11/site-packages/langflow/cache/base.py", line 25, in wrapper
    return func(*args, **kwargs)
           ^^^^^^^^^^^^^^^^^^^^^
  File "/Library/Frameworks/Python.framework/Versions/3.11/lib/python3.11/site-packages/langflow/cache/base.py", line 119, in save_binary_file
    raise ValueError(f"File {file_name} is not accepted")
ValueError: File  is not accepted
2023-06-14 12:55:11,376 - ERROR - File  is not accepted
Traceback (most recent call last):
  File "/Library/Frameworks/Python.framework/Versions/3.11/lib/python3.11/site-packages/langflow/api/validate.py", line 47, in post_validate_node
    graph = build_graph(data)
            ^^^^^^^^^^^^^^^^^
  File "/Library/Frameworks/Python.framework/Versions/3.11/lib/python3.11/site-packages/langflow/interface/run.py", line 50, in build_graph
    return Graph(nodes, edges)
           ^^^^^^^^^^^^^^^^^^^
  File "/Library/Frameworks/Python.framework/Versions/3.11/lib/python3.11/site-packages/langflow/graph/graph.py", line 43, in __init__
    self._build_graph()
  File "/Library/Frameworks/Python.framework/Versions/3.11/lib/python3.11/site-packages/langflow/graph/graph.py", line 56, in _build_graph
    node._build_params()
  File "/Library/Frameworks/Python.framework/Versions/3.11/lib/python3.11/site-packages/langflow/graph/base.py", line 93, in _build_params
    file_path = cache_utils.save_binary_file(
                ^^^^^^^^^^^^^^^^^^^^^^^^^^^^^
  File "/Library/Frameworks/Python.framework/Versions/3.11/lib/python3.11/site-packages/langflow/cache/base.py", line 25, in wrapper
    return func(*args, **kwargs)
           ^^^^^^^^^^^^^^^^^^^^^
  File "/Library/Frameworks/Python.framework/Versions/3.11/lib/python3.11/site-packages/langflow/cache/base.py", line 119, in save_binary_file
    raise ValueError(f"File {file_name} is not accepted")
ValueError: File  is not accepted
2023-06-14 12:55:14,187 - ERROR - File  is not accepted
Traceback (most recent call last):
  File "/Library/Frameworks/Python.framework/Versions/3.11/lib/python3.11/site-packages/langflow/api/validate.py", line 47, in post_validate_node
    graph = build_graph(data)
            ^^^^^^^^^^^^^^^^^
  File "/Library/Frameworks/Python.framework/Versions/3.11/lib/python3.11/site-packages/langflow/interface/run.py", line 50, in build_graph
    return Graph(nodes, edges)
           ^^^^^^^^^^^^^^^^^^^
  File "/Library/Frameworks/Python.framework/Versions/3.11/lib/python3.11/site-packages/langflow/graph/graph.py", line 43, in __init__
    self._build_graph()
  File "/Library/Frameworks/Python.framework/Versions/3.11/lib/python3.11/site-packages/langflow/graph/graph.py", line 56, in _build_graph
    node._build_params()
  File "/Library/Frameworks/Python.framework/Versions/3.11/lib/python3.11/site-packages/langflow/graph/base.py", line 93, in _build_params
    file_path = cache_utils.save_binary_file(
                ^^^^^^^^^^^^^^^^^^^^^^^^^^^^^
  File "/Library/Frameworks/Python.framework/Versions/3.11/lib/python3.11/site-packages/langflow/cache/base.py", line 25, in wrapper
    return func(*args, **kwargs)
           ^^^^^^^^^^^^^^^^^^^^^
  File "/Library/Frameworks/Python.framework/Versions/3.11/lib/python3.11/site-packages/langflow/cache/base.py", line 119, in save_binary_file
    raise ValueError(f"File {file_name} is not accepted")
ValueError: File  is not accepted
2023-06-14 12:55:14,200 - ERROR - File  is not accepted
Traceback (most recent call last):
  File "/Library/Frameworks/Python.framework/Versions/3.11/lib/python3.11/site-packages/langflow/api/validate.py", line 47, in post_validate_node
    graph = build_graph(data)
            ^^^^^^^^^^^^^^^^^
  File "/Library/Frameworks/Python.framework/Versions/3.11/lib/python3.11/site-packages/langflow/interface/run.py", line 50, in build_graph
    return Graph(nodes, edges)
           ^^^^^^^^^^^^^^^^^^^
  File "/Library/Frameworks/Python.framework/Versions/3.11/lib/python3.11/site-packages/langflow/graph/graph.py", line 43, in __init__
    self._build_graph()
  File "/Library/Frameworks/Python.framework/Versions/3.11/lib/python3.11/site-packages/langflow/graph/graph.py", line 56, in _build_graph
    node._build_params()
  File "/Library/Frameworks/Python.framework/Versions/3.11/lib/python3.11/site-packages/langflow/graph/base.py", line 93, in _build_params
    file_path = cache_utils.save_binary_file(
                ^^^^^^^^^^^^^^^^^^^^^^^^^^^^^
  File "/Library/Frameworks/Python.framework/Versions/3.11/lib/python3.11/site-packages/langflow/cache/base.py", line 25, in wrapper
    return func(*args, **kwargs)
           ^^^^^^^^^^^^^^^^^^^^^
  File "/Library/Frameworks/Python.framework/Versions/3.11/lib/python3.11/site-packages/langflow/cache/base.py", line 119, in save_binary_file
    raise ValueError(f"File {file_name} is not accepted")
ValueError: File  is not accepted
2023-06-14 12:55:14,201 - ERROR - File  is not accepted
Traceback (most recent call last):
  File "/Library/Frameworks/Python.framework/Versions/3.11/lib/python3.11/site-packages/langflow/api/validate.py", line 47, in post_validate_node
    graph = build_graph(data)
            ^^^^^^^^^^^^^^^^^
  File "/Library/Frameworks/Python.framework/Versions/3.11/lib/python3.11/site-packages/langflow/interface/run.py", line 50, in build_graph
    return Graph(nodes, edges)
           ^^^^^^^^^^^^^^^^^^^
  File "/Library/Frameworks/Python.framework/Versions/3.11/lib/python3.11/site-packages/langflow/graph/graph.py", line 43, in __init__
    self._build_graph()
  File "/Library/Frameworks/Python.framework/Versions/3.11/lib/python3.11/site-packages/langflow/graph/graph.py", line 56, in _build_graph
    node._build_params()
  File "/Library/Frameworks/Python.framework/Versions/3.11/lib/python3.11/site-packages/langflow/graph/base.py", line 93, in _build_params
    file_path = cache_utils.save_binary_file(
                ^^^^^^^^^^^^^^^^^^^^^^^^^^^^^
  File "/Library/Frameworks/Python.framework/Versions/3.11/lib/python3.11/site-packages/langflow/cache/base.py", line 25, in wrapper
    return func(*args, **kwargs)
           ^^^^^^^^^^^^^^^^^^^^^
  File "/Library/Frameworks/Python.framework/Versions/3.11/lib/python3.11/site-packages/langflow/cache/base.py", line 119, in save_binary_file
    raise ValueError(f"File {file_name} is not accepted")
ValueError: File  is not accepted
2023-06-14 12:55:14,201 - ERROR - File  is not accepted
Traceback (most recent call last):
  File "/Library/Frameworks/Python.framework/Versions/3.11/lib/python3.11/site-packages/langflow/api/validate.py", line 47, in post_validate_node
    graph = build_graph(data)
            ^^^^^^^^^^^^^^^^^
  File "/Library/Frameworks/Python.framework/Versions/3.11/lib/python3.11/site-packages/langflow/interface/run.py", line 50, in build_graph
    return Graph(nodes, edges)
           ^^^^^^^^^^^^^^^^^^^
  File "/Library/Frameworks/Python.framework/Versions/3.11/lib/python3.11/site-packages/langflow/graph/graph.py", line 43, in __init__
    self._build_graph()
  File "/Library/Frameworks/Python.framework/Versions/3.11/lib/python3.11/site-packages/langflow/graph/graph.py", line 56, in _build_graph
    node._build_params()
  File "/Library/Frameworks/Python.framework/Versions/3.11/lib/python3.11/site-packages/langflow/graph/base.py", line 93, in _build_params
    file_path = cache_utils.save_binary_file(
                ^^^^^^^^^^^^^^^^^^^^^^^^^^^^^
  File "/Library/Frameworks/Python.framework/Versions/3.11/lib/python3.11/site-packages/langflow/cache/base.py", line 25, in wrapper
    return func(*args, **kwargs)
           ^^^^^^^^^^^^^^^^^^^^^
  File "/Library/Frameworks/Python.framework/Versions/3.11/lib/python3.11/site-packages/langflow/cache/base.py", line 119, in save_binary_file
    raise ValueError(f"File {file_name} is not accepted")
ValueError: File  is not accepted
2023-06-14 12:55:14,202 - ERROR - File  is not accepted
Traceback (most recent call last):
  File "/Library/Frameworks/Python.framework/Versions/3.11/lib/python3.11/site-packages/langflow/api/validate.py", line 47, in post_validate_node
    graph = build_graph(data)
            ^^^^^^^^^^^^^^^^^
  File "/Library/Frameworks/Python.framework/Versions/3.11/lib/python3.11/site-packages/langflow/interface/run.py", line 50, in build_graph
    return Graph(nodes, edges)
           ^^^^^^^^^^^^^^^^^^^
  File "/Library/Frameworks/Python.framework/Versions/3.11/lib/python3.11/site-packages/langflow/graph/graph.py", line 43, in __init__
    self._build_graph()
  File "/Library/Frameworks/Python.framework/Versions/3.11/lib/python3.11/site-packages/langflow/graph/graph.py", line 56, in _build_graph
    node._build_params()
  File "/Library/Frameworks/Python.framework/Versions/3.11/lib/python3.11/site-packages/langflow/graph/base.py", line 93, in _build_params
    file_path = cache_utils.save_binary_file(
                ^^^^^^^^^^^^^^^^^^^^^^^^^^^^^
  File "/Library/Frameworks/Python.framework/Versions/3.11/lib/python3.11/site-packages/langflow/cache/base.py", line 25, in wrapper
    return func(*args, **kwargs)
           ^^^^^^^^^^^^^^^^^^^^^
  File "/Library/Frameworks/Python.framework/Versions/3.11/lib/python3.11/site-packages/langflow/cache/base.py", line 119, in save_binary_file
    raise ValueError(f"File {file_name} is not accepted")
ValueError: File  is not accepted
2023-06-14 12:55:14,202 - ERROR - File  is not accepted
Traceback (most recent call last):
  File "/Library/Frameworks/Python.framework/Versions/3.11/lib/python3.11/site-packages/langflow/api/validate.py", line 47, in post_validate_node
    graph = build_graph(data)
            ^^^^^^^^^^^^^^^^^
  File "/Library/Frameworks/Python.framework/Versions/3.11/lib/python3.11/site-packages/langflow/interface/run.py", line 50, in build_graph
    return Graph(nodes, edges)
           ^^^^^^^^^^^^^^^^^^^
  File "/Library/Frameworks/Python.framework/Versions/3.11/lib/python3.11/site-packages/langflow/graph/graph.py", line 43, in __init__
    self._build_graph()
  File "/Library/Frameworks/Python.framework/Versions/3.11/lib/python3.11/site-packages/langflow/graph/graph.py", line 56, in _build_graph
    node._build_params()
  File "/Library/Frameworks/Python.framework/Versions/3.11/lib/python3.11/site-packages/langflow/graph/base.py", line 93, in _build_params
    file_path = cache_utils.save_binary_file(
                ^^^^^^^^^^^^^^^^^^^^^^^^^^^^^
  File "/Library/Frameworks/Python.framework/Versions/3.11/lib/python3.11/site-packages/langflow/cache/base.py", line 25, in wrapper
    return func(*args, **kwargs)
           ^^^^^^^^^^^^^^^^^^^^^
  File "/Library/Frameworks/Python.framework/Versions/3.11/lib/python3.11/site-packages/langflow/cache/base.py", line 119, in save_binary_file
    raise ValueError(f"File {file_name} is not accepted")
ValueError: File  is not accepted
2023-06-14 12:55:14,276 - ERROR - File  is not accepted
Traceback (most recent call last):
  File "/Library/Frameworks/Python.framework/Versions/3.11/lib/python3.11/site-packages/langflow/api/validate.py", line 47, in post_validate_node
    graph = build_graph(data)
            ^^^^^^^^^^^^^^^^^
  File "/Library/Frameworks/Python.framework/Versions/3.11/lib/python3.11/site-packages/langflow/interface/run.py", line 50, in build_graph
    return Graph(nodes, edges)
           ^^^^^^^^^^^^^^^^^^^
  File "/Library/Frameworks/Python.framework/Versions/3.11/lib/python3.11/site-packages/langflow/graph/graph.py", line 43, in __init__
    self._build_graph()
  File "/Library/Frameworks/Python.framework/Versions/3.11/lib/python3.11/site-packages/langflow/graph/graph.py", line 56, in _build_graph
    node._build_params()
  File "/Library/Frameworks/Python.framework/Versions/3.11/lib/python3.11/site-packages/langflow/graph/base.py", line 93, in _build_params
    file_path = cache_utils.save_binary_file(
                ^^^^^^^^^^^^^^^^^^^^^^^^^^^^^
  File "/Library/Frameworks/Python.framework/Versions/3.11/lib/python3.11/site-packages/langflow/cache/base.py", line 25, in wrapper
    return func(*args, **kwargs)
           ^^^^^^^^^^^^^^^^^^^^^
  File "/Library/Frameworks/Python.framework/Versions/3.11/lib/python3.11/site-packages/langflow/cache/base.py", line 119, in save_binary_file
    raise ValueError(f"File {file_name} is not accepted")
ValueError: File  is not accepted
2023-06-14 12:56:23,794 - ERROR - File  is not accepted
Traceback (most recent call last):
  File "/Library/Frameworks/Python.framework/Versions/3.11/lib/python3.11/site-packages/langflow/api/validate.py", line 47, in post_validate_node
    graph = build_graph(data)
            ^^^^^^^^^^^^^^^^^
  File "/Library/Frameworks/Python.framework/Versions/3.11/lib/python3.11/site-packages/langflow/interface/run.py", line 50, in build_graph
    return Graph(nodes, edges)
           ^^^^^^^^^^^^^^^^^^^
  File "/Library/Frameworks/Python.framework/Versions/3.11/lib/python3.11/site-packages/langflow/graph/graph.py", line 43, in __init__
    self._build_graph()
  File "/Library/Frameworks/Python.framework/Versions/3.11/lib/python3.11/site-packages/langflow/graph/graph.py", line 56, in _build_graph
    node._build_params()
  File "/Library/Frameworks/Python.framework/Versions/3.11/lib/python3.11/site-packages/langflow/graph/base.py", line 93, in _build_params
    file_path = cache_utils.save_binary_file(
                ^^^^^^^^^^^^^^^^^^^^^^^^^^^^^
  File "/Library/Frameworks/Python.framework/Versions/3.11/lib/python3.11/site-packages/langflow/cache/base.py", line 25, in wrapper
    return func(*args, **kwargs)
           ^^^^^^^^^^^^^^^^^^^^^
  File "/Library/Frameworks/Python.framework/Versions/3.11/lib/python3.11/site-packages/langflow/cache/base.py", line 119, in save_binary_file
    raise ValueError(f"File {file_name} is not accepted")
ValueError: File  is not accepted
2023-06-14 12:56:23,797 - ERROR - File  is not accepted
Traceback (most recent call last):
  File "/Library/Frameworks/Python.framework/Versions/3.11/lib/python3.11/site-packages/langflow/api/validate.py", line 47, in post_validate_node
    graph = build_graph(data)
            ^^^^^^^^^^^^^^^^^
  File "/Library/Frameworks/Python.framework/Versions/3.11/lib/python3.11/site-packages/langflow/interface/run.py", line 50, in build_graph
    return Graph(nodes, edges)
           ^^^^^^^^^^^^^^^^^^^
  File "/Library/Frameworks/Python.framework/Versions/3.11/lib/python3.11/site-packages/langflow/graph/graph.py", line 43, in __init__
    self._build_graph()
  File "/Library/Frameworks/Python.framework/Versions/3.11/lib/python3.11/site-packages/langflow/graph/graph.py", line 56, in _build_graph
    node._build_params()
  File "/Library/Frameworks/Python.framework/Versions/3.11/lib/python3.11/site-packages/langflow/graph/base.py", line 93, in _build_params
    file_path = cache_utils.save_binary_file(
                ^^^^^^^^^^^^^^^^^^^^^^^^^^^^^
  File "/Library/Frameworks/Python.framework/Versions/3.11/lib/python3.11/site-packages/langflow/cache/base.py", line 25, in wrapper
    return func(*args, **kwargs)
           ^^^^^^^^^^^^^^^^^^^^^
  File "/Library/Frameworks/Python.framework/Versions/3.11/lib/python3.11/site-packages/langflow/cache/base.py", line 119, in save_binary_file
    raise ValueError(f"File {file_name} is not accepted")
ValueError: File  is not accepted
2023-06-14 12:56:23,801 - ERROR - File  is not accepted
Traceback (most recent call last):
  File "/Library/Frameworks/Python.framework/Versions/3.11/lib/python3.11/site-packages/langflow/api/validate.py", line 47, in post_validate_node
    graph = build_graph(data)
            ^^^^^^^^^^^^^^^^^
  File "/Library/Frameworks/Python.framework/Versions/3.11/lib/python3.11/site-packages/langflow/interface/run.py", line 50, in build_graph
    return Graph(nodes, edges)
           ^^^^^^^^^^^^^^^^^^^
  File "/Library/Frameworks/Python.framework/Versions/3.11/lib/python3.11/site-packages/langflow/graph/graph.py", line 43, in __init__
    self._build_graph()
  File "/Library/Frameworks/Python.framework/Versions/3.11/lib/python3.11/site-packages/langflow/graph/graph.py", line 56, in _build_graph
    node._build_params()
  File "/Library/Frameworks/Python.framework/Versions/3.11/lib/python3.11/site-packages/langflow/graph/base.py", line 93, in _build_params
    file_path = cache_utils.save_binary_file(
                ^^^^^^^^^^^^^^^^^^^^^^^^^^^^^
  File "/Library/Frameworks/Python.framework/Versions/3.11/lib/python3.11/site-packages/langflow/cache/base.py", line 25, in wrapper
    return func(*args, **kwargs)
           ^^^^^^^^^^^^^^^^^^^^^
  File "/Library/Frameworks/Python.framework/Versions/3.11/lib/python3.11/site-packages/langflow/cache/base.py", line 119, in save_binary_file
    raise ValueError(f"File {file_name} is not accepted")
ValueError: File  is not accepted
2023-06-14 12:56:23,801 - ERROR - File  is not accepted
Traceback (most recent call last):
  File "/Library/Frameworks/Python.framework/Versions/3.11/lib/python3.11/site-packages/langflow/api/validate.py", line 47, in post_validate_node
    graph = build_graph(data)
            ^^^^^^^^^^^^^^^^^
  File "/Library/Frameworks/Python.framework/Versions/3.11/lib/python3.11/site-packages/langflow/interface/run.py", line 50, in build_graph
    return Graph(nodes, edges)
           ^^^^^^^^^^^^^^^^^^^
  File "/Library/Frameworks/Python.framework/Versions/3.11/lib/python3.11/site-packages/langflow/graph/graph.py", line 43, in __init__
    self._build_graph()
  File "/Library/Frameworks/Python.framework/Versions/3.11/lib/python3.11/site-packages/langflow/graph/graph.py", line 56, in _build_graph
    node._build_params()
  File "/Library/Frameworks/Python.framework/Versions/3.11/lib/python3.11/site-packages/langflow/graph/base.py", line 93, in _build_params
    file_path = cache_utils.save_binary_file(
                ^^^^^^^^^^^^^^^^^^^^^^^^^^^^^
  File "/Library/Frameworks/Python.framework/Versions/3.11/lib/python3.11/site-packages/langflow/cache/base.py", line 25, in wrapper
    return func(*args, **kwargs)
           ^^^^^^^^^^^^^^^^^^^^^
  File "/Library/Frameworks/Python.framework/Versions/3.11/lib/python3.11/site-packages/langflow/cache/base.py", line 119, in save_binary_file
    raise ValueError(f"File {file_name} is not accepted")
ValueError: File  is not accepted
2023-06-14 12:56:23,830 - ERROR - File  is not accepted
Traceback (most recent call last):
  File "/Library/Frameworks/Python.framework/Versions/3.11/lib/python3.11/site-packages/langflow/api/validate.py", line 47, in post_validate_node
    graph = build_graph(data)
            ^^^^^^^^^^^^^^^^^
  File "/Library/Frameworks/Python.framework/Versions/3.11/lib/python3.11/site-packages/langflow/interface/run.py", line 50, in build_graph
    return Graph(nodes, edges)
           ^^^^^^^^^^^^^^^^^^^
  File "/Library/Frameworks/Python.framework/Versions/3.11/lib/python3.11/site-packages/langflow/graph/graph.py", line 43, in __init__
    self._build_graph()
  File "/Library/Frameworks/Python.framework/Versions/3.11/lib/python3.11/site-packages/langflow/graph/graph.py", line 56, in _build_graph
    node._build_params()
  File "/Library/Frameworks/Python.framework/Versions/3.11/lib/python3.11/site-packages/langflow/graph/base.py", line 93, in _build_params
    file_path = cache_utils.save_binary_file(
                ^^^^^^^^^^^^^^^^^^^^^^^^^^^^^
  File "/Library/Frameworks/Python.framework/Versions/3.11/lib/python3.11/site-packages/langflow/cache/base.py", line 25, in wrapper
    return func(*args, **kwargs)
           ^^^^^^^^^^^^^^^^^^^^^
  File "/Library/Frameworks/Python.framework/Versions/3.11/lib/python3.11/site-packages/langflow/cache/base.py", line 119, in save_binary_file
    raise ValueError(f"File {file_name} is not accepted")
ValueError: File  is not accepted
2023-06-14 12:56:23,846 - ERROR - File  is not accepted
Traceback (most recent call last):
  File "/Library/Frameworks/Python.framework/Versions/3.11/lib/python3.11/site-packages/langflow/api/validate.py", line 47, in post_validate_node
    graph = build_graph(data)
            ^^^^^^^^^^^^^^^^^
  File "/Library/Frameworks/Python.framework/Versions/3.11/lib/python3.11/site-packages/langflow/interface/run.py", line 50, in build_graph
    return Graph(nodes, edges)
           ^^^^^^^^^^^^^^^^^^^
  File "/Library/Frameworks/Python.framework/Versions/3.11/lib/python3.11/site-packages/langflow/graph/graph.py", line 43, in __init__
    self._build_graph()
  File "/Library/Frameworks/Python.framework/Versions/3.11/lib/python3.11/site-packages/langflow/graph/graph.py", line 56, in _build_graph
    node._build_params()
  File "/Library/Frameworks/Python.framework/Versions/3.11/lib/python3.11/site-packages/langflow/graph/base.py", line 93, in _build_params
    file_path = cache_utils.save_binary_file(
                ^^^^^^^^^^^^^^^^^^^^^^^^^^^^^
  File "/Library/Frameworks/Python.framework/Versions/3.11/lib/python3.11/site-packages/langflow/cache/base.py", line 25, in wrapper
    return func(*args, **kwargs)
           ^^^^^^^^^^^^^^^^^^^^^
  File "/Library/Frameworks/Python.framework/Versions/3.11/lib/python3.11/site-packages/langflow/cache/base.py", line 119, in save_binary_file
    raise ValueError(f"File {file_name} is not accepted")
ValueError: File  is not accepted
2023-06-14 12:56:23,883 - ERROR - File  is not accepted
Traceback (most recent call last):
  File "/Library/Frameworks/Python.framework/Versions/3.11/lib/python3.11/site-packages/langflow/api/validate.py", line 47, in post_validate_node
    graph = build_graph(data)
            ^^^^^^^^^^^^^^^^^
  File "/Library/Frameworks/Python.framework/Versions/3.11/lib/python3.11/site-packages/langflow/interface/run.py", line 50, in build_graph
    return Graph(nodes, edges)
           ^^^^^^^^^^^^^^^^^^^
  File "/Library/Frameworks/Python.framework/Versions/3.11/lib/python3.11/site-packages/langflow/graph/graph.py", line 43, in __init__
    self._build_graph()
  File "/Library/Frameworks/Python.framework/Versions/3.11/lib/python3.11/site-packages/langflow/graph/graph.py", line 56, in _build_graph
    node._build_params()
  File "/Library/Frameworks/Python.framework/Versions/3.11/lib/python3.11/site-packages/langflow/graph/base.py", line 93, in _build_params
    file_path = cache_utils.save_binary_file(
                ^^^^^^^^^^^^^^^^^^^^^^^^^^^^^
  File "/Library/Frameworks/Python.framework/Versions/3.11/lib/python3.11/site-packages/langflow/cache/base.py", line 25, in wrapper
    return func(*args, **kwargs)
           ^^^^^^^^^^^^^^^^^^^^^
  File "/Library/Frameworks/Python.framework/Versions/3.11/lib/python3.11/site-packages/langflow/cache/base.py", line 119, in save_binary_file
    raise ValueError(f"File {file_name} is not accepted")
ValueError: File  is not accepted
2023-06-14 13:06:37,864 - ERROR - 1006
Traceback (most recent call last):
  File "/Library/Frameworks/Python.framework/Versions/3.11/lib/python3.11/site-packages/langflow/api/chat_manager.py", line 165, in handle_websocket
    json_payload = await websocket.receive_json()
                   ^^^^^^^^^^^^^^^^^^^^^^^^^^^^^^
  File "/Library/Frameworks/Python.framework/Versions/3.11/lib/python3.11/site-packages/starlette/websockets.py", line 133, in receive_json
    self._raise_on_disconnect(message)
  File "/Library/Frameworks/Python.framework/Versions/3.11/lib/python3.11/site-packages/starlette/websockets.py", line 105, in _raise_on_disconnect
    raise WebSocketDisconnect(message["code"])
starlette.websockets.WebSocketDisconnect: 1006
2023-06-14 13:06:37,927 - ERROR - Cannot call "send" once a close message has been sent.
Traceback (most recent call last):
  File "/Library/Frameworks/Python.framework/Versions/3.11/lib/python3.11/site-packages/langflow/api/chat_manager.py", line 165, in handle_websocket
    json_payload = await websocket.receive_json()
                   ^^^^^^^^^^^^^^^^^^^^^^^^^^^^^^
  File "/Library/Frameworks/Python.framework/Versions/3.11/lib/python3.11/site-packages/starlette/websockets.py", line 133, in receive_json
    self._raise_on_disconnect(message)
  File "/Library/Frameworks/Python.framework/Versions/3.11/lib/python3.11/site-packages/starlette/websockets.py", line 105, in _raise_on_disconnect
    raise WebSocketDisconnect(message["code"])
starlette.websockets.WebSocketDisconnect: 1006

During handling of the above exception, another exception occurred:

Traceback (most recent call last):
  File "/Library/Frameworks/Python.framework/Versions/3.11/lib/python3.11/site-packages/langflow/api/chat_manager.py", line 181, in handle_websocket
    await self.active_connections[client_id].close(
  File "/Library/Frameworks/Python.framework/Versions/3.11/lib/python3.11/site-packages/starlette/websockets.py", line 180, in close
    await self.send(
  File "/Library/Frameworks/Python.framework/Versions/3.11/lib/python3.11/site-packages/starlette/websockets.py", line 85, in send
    await self._send(message)
  File "/Library/Frameworks/Python.framework/Versions/3.11/lib/python3.11/site-packages/starlette/middleware/exceptions.py", line 65, in sender
    await send(message)
  File "/Library/Frameworks/Python.framework/Versions/3.11/lib/python3.11/site-packages/uvicorn/protocols/websockets/websockets_impl.py", line 329, in asgi_send
    raise RuntimeError(msg % message_type)
RuntimeError: Unexpected ASGI message 'websocket.close', after sending 'websocket.close'.

During handling of the above exception, another exception occurred:

Traceback (most recent call last):
  File "/Library/Frameworks/Python.framework/Versions/3.11/lib/python3.11/site-packages/langflow/api/chat_manager.py", line 189, in handle_websocket
    await connection.close(code=1000, reason="Client disconnected")
  File "/Library/Frameworks/Python.framework/Versions/3.11/lib/python3.11/site-packages/starlette/websockets.py", line 180, in close
    await self.send(
  File "/Library/Frameworks/Python.framework/Versions/3.11/lib/python3.11/site-packages/starlette/websockets.py", line 87, in send
    raise RuntimeError('Cannot call "send" once a close message has been sent.')
RuntimeError: Cannot call "send" once a close message has been sent.
2023-06-14 16:17:50,833 - ERROR - File  is not accepted
Traceback (most recent call last):
  File "/Library/Frameworks/Python.framework/Versions/3.11/lib/python3.11/site-packages/langflow/api/validate.py", line 47, in post_validate_node
    graph = build_graph(data)
            ^^^^^^^^^^^^^^^^^
  File "/Library/Frameworks/Python.framework/Versions/3.11/lib/python3.11/site-packages/langflow/interface/run.py", line 50, in build_graph
    return Graph(nodes, edges)
           ^^^^^^^^^^^^^^^^^^^
  File "/Library/Frameworks/Python.framework/Versions/3.11/lib/python3.11/site-packages/langflow/graph/graph.py", line 43, in __init__
    self._build_graph()
  File "/Library/Frameworks/Python.framework/Versions/3.11/lib/python3.11/site-packages/langflow/graph/graph.py", line 56, in _build_graph
    node._build_params()
  File "/Library/Frameworks/Python.framework/Versions/3.11/lib/python3.11/site-packages/langflow/graph/base.py", line 93, in _build_params
    file_path = cache_utils.save_binary_file(
                ^^^^^^^^^^^^^^^^^^^^^^^^^^^^^
  File "/Library/Frameworks/Python.framework/Versions/3.11/lib/python3.11/site-packages/langflow/cache/base.py", line 25, in wrapper
    return func(*args, **kwargs)
           ^^^^^^^^^^^^^^^^^^^^^
  File "/Library/Frameworks/Python.framework/Versions/3.11/lib/python3.11/site-packages/langflow/cache/base.py", line 119, in save_binary_file
    raise ValueError(f"File {file_name} is not accepted")
ValueError: File  is not accepted
2023-06-14 16:17:50,833 - ERROR - File  is not accepted
Traceback (most recent call last):
  File "/Library/Frameworks/Python.framework/Versions/3.11/lib/python3.11/site-packages/langflow/api/validate.py", line 47, in post_validate_node
    graph = build_graph(data)
            ^^^^^^^^^^^^^^^^^
  File "/Library/Frameworks/Python.framework/Versions/3.11/lib/python3.11/site-packages/langflow/interface/run.py", line 50, in build_graph
    return Graph(nodes, edges)
           ^^^^^^^^^^^^^^^^^^^
  File "/Library/Frameworks/Python.framework/Versions/3.11/lib/python3.11/site-packages/langflow/graph/graph.py", line 43, in __init__
    self._build_graph()
  File "/Library/Frameworks/Python.framework/Versions/3.11/lib/python3.11/site-packages/langflow/graph/graph.py", line 56, in _build_graph
    node._build_params()
  File "/Library/Frameworks/Python.framework/Versions/3.11/lib/python3.11/site-packages/langflow/graph/base.py", line 93, in _build_params
    file_path = cache_utils.save_binary_file(
                ^^^^^^^^^^^^^^^^^^^^^^^^^^^^^
  File "/Library/Frameworks/Python.framework/Versions/3.11/lib/python3.11/site-packages/langflow/cache/base.py", line 25, in wrapper
    return func(*args, **kwargs)
           ^^^^^^^^^^^^^^^^^^^^^
  File "/Library/Frameworks/Python.framework/Versions/3.11/lib/python3.11/site-packages/langflow/cache/base.py", line 119, in save_binary_file
    raise ValueError(f"File {file_name} is not accepted")
ValueError: File  is not accepted
2023-06-14 16:17:50,835 - ERROR - File  is not accepted
Traceback (most recent call last):
  File "/Library/Frameworks/Python.framework/Versions/3.11/lib/python3.11/site-packages/langflow/api/validate.py", line 47, in post_validate_node
    graph = build_graph(data)
            ^^^^^^^^^^^^^^^^^
  File "/Library/Frameworks/Python.framework/Versions/3.11/lib/python3.11/site-packages/langflow/interface/run.py", line 50, in build_graph
    return Graph(nodes, edges)
           ^^^^^^^^^^^^^^^^^^^
  File "/Library/Frameworks/Python.framework/Versions/3.11/lib/python3.11/site-packages/langflow/graph/graph.py", line 43, in __init__
    self._build_graph()
  File "/Library/Frameworks/Python.framework/Versions/3.11/lib/python3.11/site-packages/langflow/graph/graph.py", line 56, in _build_graph
    node._build_params()
  File "/Library/Frameworks/Python.framework/Versions/3.11/lib/python3.11/site-packages/langflow/graph/base.py", line 93, in _build_params
    file_path = cache_utils.save_binary_file(
                ^^^^^^^^^^^^^^^^^^^^^^^^^^^^^
  File "/Library/Frameworks/Python.framework/Versions/3.11/lib/python3.11/site-packages/langflow/cache/base.py", line 25, in wrapper
    return func(*args, **kwargs)
           ^^^^^^^^^^^^^^^^^^^^^
  File "/Library/Frameworks/Python.framework/Versions/3.11/lib/python3.11/site-packages/langflow/cache/base.py", line 119, in save_binary_file
    raise ValueError(f"File {file_name} is not accepted")
ValueError: File  is not accepted
2023-06-14 16:17:50,838 - ERROR - File  is not accepted
Traceback (most recent call last):
  File "/Library/Frameworks/Python.framework/Versions/3.11/lib/python3.11/site-packages/langflow/api/validate.py", line 47, in post_validate_node
    graph = build_graph(data)
            ^^^^^^^^^^^^^^^^^
  File "/Library/Frameworks/Python.framework/Versions/3.11/lib/python3.11/site-packages/langflow/interface/run.py", line 50, in build_graph
    return Graph(nodes, edges)
           ^^^^^^^^^^^^^^^^^^^
  File "/Library/Frameworks/Python.framework/Versions/3.11/lib/python3.11/site-packages/langflow/graph/graph.py", line 43, in __init__
    self._build_graph()
  File "/Library/Frameworks/Python.framework/Versions/3.11/lib/python3.11/site-packages/langflow/graph/graph.py", line 56, in _build_graph
    node._build_params()
  File "/Library/Frameworks/Python.framework/Versions/3.11/lib/python3.11/site-packages/langflow/graph/base.py", line 93, in _build_params
    file_path = cache_utils.save_binary_file(
                ^^^^^^^^^^^^^^^^^^^^^^^^^^^^^
  File "/Library/Frameworks/Python.framework/Versions/3.11/lib/python3.11/site-packages/langflow/cache/base.py", line 25, in wrapper
    return func(*args, **kwargs)
           ^^^^^^^^^^^^^^^^^^^^^
  File "/Library/Frameworks/Python.framework/Versions/3.11/lib/python3.11/site-packages/langflow/cache/base.py", line 119, in save_binary_file
    raise ValueError(f"File {file_name} is not accepted")
ValueError: File  is not accepted
2023-06-14 16:17:50,861 - ERROR - File  is not accepted
Traceback (most recent call last):
  File "/Library/Frameworks/Python.framework/Versions/3.11/lib/python3.11/site-packages/langflow/api/validate.py", line 47, in post_validate_node
    graph = build_graph(data)
            ^^^^^^^^^^^^^^^^^
  File "/Library/Frameworks/Python.framework/Versions/3.11/lib/python3.11/site-packages/langflow/interface/run.py", line 50, in build_graph
    return Graph(nodes, edges)
           ^^^^^^^^^^^^^^^^^^^
  File "/Library/Frameworks/Python.framework/Versions/3.11/lib/python3.11/site-packages/langflow/graph/graph.py", line 43, in __init__
    self._build_graph()
  File "/Library/Frameworks/Python.framework/Versions/3.11/lib/python3.11/site-packages/langflow/graph/graph.py", line 56, in _build_graph
    node._build_params()
  File "/Library/Frameworks/Python.framework/Versions/3.11/lib/python3.11/site-packages/langflow/graph/base.py", line 93, in _build_params
    file_path = cache_utils.save_binary_file(
                ^^^^^^^^^^^^^^^^^^^^^^^^^^^^^
  File "/Library/Frameworks/Python.framework/Versions/3.11/lib/python3.11/site-packages/langflow/cache/base.py", line 25, in wrapper
    return func(*args, **kwargs)
           ^^^^^^^^^^^^^^^^^^^^^
  File "/Library/Frameworks/Python.framework/Versions/3.11/lib/python3.11/site-packages/langflow/cache/base.py", line 119, in save_binary_file
    raise ValueError(f"File {file_name} is not accepted")
ValueError: File  is not accepted
2023-06-14 16:17:50,861 - ERROR - File  is not accepted
Traceback (most recent call last):
  File "/Library/Frameworks/Python.framework/Versions/3.11/lib/python3.11/site-packages/langflow/api/validate.py", line 47, in post_validate_node
    graph = build_graph(data)
            ^^^^^^^^^^^^^^^^^
  File "/Library/Frameworks/Python.framework/Versions/3.11/lib/python3.11/site-packages/langflow/interface/run.py", line 50, in build_graph
    return Graph(nodes, edges)
           ^^^^^^^^^^^^^^^^^^^
  File "/Library/Frameworks/Python.framework/Versions/3.11/lib/python3.11/site-packages/langflow/graph/graph.py", line 43, in __init__
    self._build_graph()
  File "/Library/Frameworks/Python.framework/Versions/3.11/lib/python3.11/site-packages/langflow/graph/graph.py", line 56, in _build_graph
    node._build_params()
  File "/Library/Frameworks/Python.framework/Versions/3.11/lib/python3.11/site-packages/langflow/graph/base.py", line 93, in _build_params
    file_path = cache_utils.save_binary_file(
                ^^^^^^^^^^^^^^^^^^^^^^^^^^^^^
  File "/Library/Frameworks/Python.framework/Versions/3.11/lib/python3.11/site-packages/langflow/cache/base.py", line 25, in wrapper
    return func(*args, **kwargs)
           ^^^^^^^^^^^^^^^^^^^^^
  File "/Library/Frameworks/Python.framework/Versions/3.11/lib/python3.11/site-packages/langflow/cache/base.py", line 119, in save_binary_file
    raise ValueError(f"File {file_name} is not accepted")
ValueError: File  is not accepted
2023-06-14 16:17:50,915 - ERROR - File  is not accepted
Traceback (most recent call last):
  File "/Library/Frameworks/Python.framework/Versions/3.11/lib/python3.11/site-packages/langflow/api/validate.py", line 47, in post_validate_node
    graph = build_graph(data)
            ^^^^^^^^^^^^^^^^^
  File "/Library/Frameworks/Python.framework/Versions/3.11/lib/python3.11/site-packages/langflow/interface/run.py", line 50, in build_graph
    return Graph(nodes, edges)
           ^^^^^^^^^^^^^^^^^^^
  File "/Library/Frameworks/Python.framework/Versions/3.11/lib/python3.11/site-packages/langflow/graph/graph.py", line 43, in __init__
    self._build_graph()
  File "/Library/Frameworks/Python.framework/Versions/3.11/lib/python3.11/site-packages/langflow/graph/graph.py", line 56, in _build_graph
    node._build_params()
  File "/Library/Frameworks/Python.framework/Versions/3.11/lib/python3.11/site-packages/langflow/graph/base.py", line 93, in _build_params
    file_path = cache_utils.save_binary_file(
                ^^^^^^^^^^^^^^^^^^^^^^^^^^^^^
  File "/Library/Frameworks/Python.framework/Versions/3.11/lib/python3.11/site-packages/langflow/cache/base.py", line 25, in wrapper
    return func(*args, **kwargs)
           ^^^^^^^^^^^^^^^^^^^^^
  File "/Library/Frameworks/Python.framework/Versions/3.11/lib/python3.11/site-packages/langflow/cache/base.py", line 119, in save_binary_file
    raise ValueError(f"File {file_name} is not accepted")
ValueError: File  is not accepted
2023-06-14 16:19:23,754 - ERROR - 1001
Traceback (most recent call last):
  File "/Library/Frameworks/Python.framework/Versions/3.11/lib/python3.11/site-packages/langflow/api/chat_manager.py", line 165, in handle_websocket
    json_payload = await websocket.receive_json()
                   ^^^^^^^^^^^^^^^^^^^^^^^^^^^^^^
  File "/Library/Frameworks/Python.framework/Versions/3.11/lib/python3.11/site-packages/starlette/websockets.py", line 133, in receive_json
    self._raise_on_disconnect(message)
  File "/Library/Frameworks/Python.framework/Versions/3.11/lib/python3.11/site-packages/starlette/websockets.py", line 105, in _raise_on_disconnect
    raise WebSocketDisconnect(message["code"])
starlette.websockets.WebSocketDisconnect: 1001
2023-06-14 16:19:23,800 - ERROR - Cannot call "send" once a close message has been sent.
Traceback (most recent call last):
  File "/Library/Frameworks/Python.framework/Versions/3.11/lib/python3.11/site-packages/langflow/api/chat_manager.py", line 165, in handle_websocket
    json_payload = await websocket.receive_json()
                   ^^^^^^^^^^^^^^^^^^^^^^^^^^^^^^
  File "/Library/Frameworks/Python.framework/Versions/3.11/lib/python3.11/site-packages/starlette/websockets.py", line 133, in receive_json
    self._raise_on_disconnect(message)
  File "/Library/Frameworks/Python.framework/Versions/3.11/lib/python3.11/site-packages/starlette/websockets.py", line 105, in _raise_on_disconnect
    raise WebSocketDisconnect(message["code"])
starlette.websockets.WebSocketDisconnect: 1001

During handling of the above exception, another exception occurred:

Traceback (most recent call last):
  File "/Library/Frameworks/Python.framework/Versions/3.11/lib/python3.11/site-packages/langflow/api/chat_manager.py", line 181, in handle_websocket
    await self.active_connections[client_id].close(
  File "/Library/Frameworks/Python.framework/Versions/3.11/lib/python3.11/site-packages/starlette/websockets.py", line 180, in close
    await self.send(
  File "/Library/Frameworks/Python.framework/Versions/3.11/lib/python3.11/site-packages/starlette/websockets.py", line 85, in send
    await self._send(message)
  File "/Library/Frameworks/Python.framework/Versions/3.11/lib/python3.11/site-packages/starlette/middleware/exceptions.py", line 65, in sender
    await send(message)
  File "/Library/Frameworks/Python.framework/Versions/3.11/lib/python3.11/site-packages/uvicorn/protocols/websockets/websockets_impl.py", line 329, in asgi_send
    raise RuntimeError(msg % message_type)
RuntimeError: Unexpected ASGI message 'websocket.close', after sending 'websocket.close'.

During handling of the above exception, another exception occurred:

Traceback (most recent call last):
  File "/Library/Frameworks/Python.framework/Versions/3.11/lib/python3.11/site-packages/langflow/api/chat_manager.py", line 189, in handle_websocket
    await connection.close(code=1000, reason="Client disconnected")
  File "/Library/Frameworks/Python.framework/Versions/3.11/lib/python3.11/site-packages/starlette/websockets.py", line 180, in close
    await self.send(
  File "/Library/Frameworks/Python.framework/Versions/3.11/lib/python3.11/site-packages/starlette/websockets.py", line 87, in send
    raise RuntimeError('Cannot call "send" once a close message has been sent.')
RuntimeError: Cannot call "send" once a close message has been sent.
2023-06-14 16:20:47,637 - ERROR - 1012
Traceback (most recent call last):
  File "/Library/Frameworks/Python.framework/Versions/3.11/lib/python3.11/site-packages/langflow/api/chat_manager.py", line 165, in handle_websocket
    json_payload = await websocket.receive_json()
                   ^^^^^^^^^^^^^^^^^^^^^^^^^^^^^^
  File "/Library/Frameworks/Python.framework/Versions/3.11/lib/python3.11/site-packages/starlette/websockets.py", line 133, in receive_json
    self._raise_on_disconnect(message)
  File "/Library/Frameworks/Python.framework/Versions/3.11/lib/python3.11/site-packages/starlette/websockets.py", line 105, in _raise_on_disconnect
    raise WebSocketDisconnect(message["code"])
starlette.websockets.WebSocketDisconnect: 1012
2023-06-14 16:20:47,674 - ERROR - Cannot call "send" once a close message has been sent.
Traceback (most recent call last):
  File "/Library/Frameworks/Python.framework/Versions/3.11/lib/python3.11/site-packages/langflow/api/chat_manager.py", line 165, in handle_websocket
    json_payload = await websocket.receive_json()
                   ^^^^^^^^^^^^^^^^^^^^^^^^^^^^^^
  File "/Library/Frameworks/Python.framework/Versions/3.11/lib/python3.11/site-packages/starlette/websockets.py", line 133, in receive_json
    self._raise_on_disconnect(message)
  File "/Library/Frameworks/Python.framework/Versions/3.11/lib/python3.11/site-packages/starlette/websockets.py", line 105, in _raise_on_disconnect
    raise WebSocketDisconnect(message["code"])
starlette.websockets.WebSocketDisconnect: 1012

During handling of the above exception, another exception occurred:

Traceback (most recent call last):
  File "/Library/Frameworks/Python.framework/Versions/3.11/lib/python3.11/site-packages/langflow/api/chat_manager.py", line 181, in handle_websocket
    await self.active_connections[client_id].close(
  File "/Library/Frameworks/Python.framework/Versions/3.11/lib/python3.11/site-packages/starlette/websockets.py", line 180, in close
    await self.send(
  File "/Library/Frameworks/Python.framework/Versions/3.11/lib/python3.11/site-packages/starlette/websockets.py", line 85, in send
    await self._send(message)
  File "/Library/Frameworks/Python.framework/Versions/3.11/lib/python3.11/site-packages/starlette/middleware/exceptions.py", line 65, in sender
    await send(message)
  File "/Library/Frameworks/Python.framework/Versions/3.11/lib/python3.11/site-packages/uvicorn/protocols/websockets/websockets_impl.py", line 329, in asgi_send
    raise RuntimeError(msg % message_type)
RuntimeError: Unexpected ASGI message 'websocket.close', after sending 'websocket.close'.

During handling of the above exception, another exception occurred:

Traceback (most recent call last):
  File "/Library/Frameworks/Python.framework/Versions/3.11/lib/python3.11/site-packages/langflow/api/chat_manager.py", line 189, in handle_websocket
    await connection.close(code=1000, reason="Client disconnected")
  File "/Library/Frameworks/Python.framework/Versions/3.11/lib/python3.11/site-packages/starlette/websockets.py", line 180, in close
    await self.send(
  File "/Library/Frameworks/Python.framework/Versions/3.11/lib/python3.11/site-packages/starlette/websockets.py", line 87, in send
    raise RuntimeError('Cannot call "send" once a close message has been sent.')
RuntimeError: Cannot call "send" once a close message has been sent.
